Workbook

Sheet Lançamentos
A1: ,
A2: Data | B2: Descrição | C2: Tipo | D2: Categoria | E2: Conta | F2: Forma de pagamento | G2: Valor | I2: Obs | J2: Mês | K2: Saldo acumulado
A3: 46204 | B3: Leite | C3: Saída | D3: Vendas | E3: Caixa | F3: Dinheiro | J3: =TEXT(A3,"yyyy-mm") -> yyyy-07 | K3: =G3 -> 0
A4: 46204 | B4: Tortelli | C4: Saída | D4: Vendas | E4: Banco Principal | J4: =TEXT(A4,"yyyy-mm") -> yyyy-07 | K4: =K3 + IF(C4="Entrada", G4, -G4) -> 0
A5: 46204 | B5: Ecila | C5: Saída | D5: Matéria Prima | E5: Banco Principal | G5: 115.8 | J5: =TEXT(A5,"yyyy-mm") -> yyyy-07 | K5: =K4 + IF(C5="Entrada", G5, -G5) -> -115.8
A6: 46204 | B6: Vendas | C6: Entrada | D6: Vendas | G6: 1762 | J6: =TEXT(A6,"yyyy-mm") -> yyyy-07 | K6: =K5 + IF(C6="Entrada", G6, -G6) -> 1646.2
A7: 46204 | B7: Vendas Ifood | C7: Entrada | D7: Vendas iFood | E7: Banco Principal | G7: 82 | J7: =TEXT(A7,"yyyy-mm") -> yyyy-07 | K7: =K6 + IF(C7="Entrada", G7, -G7) -> 1728.2
A8: 46204 | B8: Motoboy | C8: Saída | D8: iFood | E8: Banco Principal | F8: Pix | G8: 9 | J8: =TEXT(A8,"yyyy-mm") -> yyyy-07 | K8: =K7 + IF(C8="Entrada", G8, -G8) -> 1719.2
A9: 46204 | B9: Faxina | C9: Saída | D9: Salário | E9: Banco Principal | F9: Pix | G9: 1100 | J9: =TEXT(A9,"yyyy-mm") -> yyyy-07 | K9: =K8 + IF(C9="Entrada", G9, -G9) -> 619.2
A10: 46204 | B10: Canteiros ( reembolsar) | C10: Saída | D10: Manutenção | E10: Banco Principal | F10: Pix | G10: 400 | J10: =TEXT(A10,"yyyy-mm") -> yyyy-07 | K10: =K9 + IF(C10="Entrada", G10, -G10) -> 219.2
A11: 46204 | B11: Tais salário ja pago mes passado de adiantamento | C11: Saída | D11: Salário | E11: Banco Principal | F11: Pix | G11: 3000 | J11: =TEXT(A11,"yyyy-mm") -> yyyy-07 | K11: =K10 + IF(C11="Entrada", G11, -G11) -> -2780.8
A12: 46205 | B12: Vendas | C12: Entrada | D12: Vendas | G12: 1659 | J12: =TEXT(A12,"yyyy-mm") -> yyyy-07 | K12: =K11 + IF(C12="Entrada", G12, -G12) -> -1121.8
A13: 46205 | B13: Vendas Ifood | C13: Entrada | D13: Vendas iFood | E13: Banco Principal | G13: 0 | J13: =TEXT(A13,"yyyy-mm") -> yyyy-07 | K13: =K12 + IF(C13="Entrada", G13, -G13) -> -1121.8
A14: 46205 | B14: Motoboy | C14: Saída | D14: iFood | E14: Banco Principal | F14: Pix | G14: 0 | J14: =TEXT(A14,"yyyy-mm") -> yyyy-07 | K14: =K13 + IF(C14="Entrada", G14, -G14) -> -1121.8
A15: 46205 | B15: Leite | C15: Saída | D15: Matéria Prima | E15: Caixa | F15: Dinheiro | G15: 240 | J15: =TEXT(A15,"yyyy-mm") -> yyyy-07 | K15: =K14 + IF(C15="Entrada", G15, -G15) -> -1361.8
A16: 46206 | B16: Vendas | C16: Entrada | D16: Vendas | G16: 3246 | J16: =TEXT(A16,"yyyy-mm") -> yyyy-07 | K16: =K15 + IF(C16="Entrada", G16, -G16) -> 1884.2
A17: 46206 | B17: Vendas Ifood | C17: Entrada | D17: Vendas iFood | E17: Banco Principal | G17: 106 | J17: =TEXT(A17,"yyyy-mm") -> yyyy-07 | K17: =K16 + IF(C17="Entrada", G17, -G17) -> 1990.2
A18: 46206 | B18: Motoboy | C18: Saída | D18: iFood | E18: Banco Principal | F18: Pix | G18: 18 | J18: =TEXT(A18,"yyyy-mm") -> yyyy-07 | K18: =K17 + IF(C18="Entrada", G18, -G18) -> 1972.2
A19: 46206 | B19: Frutas | C19: Saída | D19: Matéria Prima | E19: Banco Principal | F19: Pix | G19: 164 | J19: =TEXT(A19,"yyyy-mm") -> yyyy-07 | K19: =K18 + IF(C19="Entrada", G19, -G19) -> 1808.2
A20: 46206 | B20: Leite | C20: Saída | D20: Matéria Prima | E20: Caixa | F20: Dinheiro | G20: 376 | J20: =TEXT(A20,"yyyy-mm") -> yyyy-07 | K20: =K19 + IF(C20="Entrada", G20, -G20) -> 1432.2
A21: 46206 | B21: Folga Luany 50+100 | C21: Saída | D21: Freelancer | E21: Banco Principal | F21: Pix | G21: 150 | J21: =TEXT(A21,"yyyy-mm") -> yyyy-07 | K21: =K20 + IF(C21="Entrada", G21, -G21) -> 1282.2
A22: 46207 | B22: Vendas | C22: Entrada | D22: Vendas | G22: 5206 | J22: =TEXT(A22,"yyyy-mm") -> yyyy-07 | K22: =K21 + IF(C22="Entrada", G22, -G22) -> 6488.2
A23: 46207 | B23: Vebdas Ifood | C23: Entrada | D23: Vendas iFood | E23: Banco Principal | G23: 150 | J23: =TEXT(A23,"yyyy-mm") -> yyyy-07 | K23: =K22 + IF(C23="Entrada", G23, -G23) -> 6638.2
A24: 46207 | B24: Motoboy | C24: Saída | D24: iFood | E24: Banco Principal | F24: Pix | G24: 35 | J24: =TEXT(A24,"yyyy-mm") -> yyyy-07 | K24: =K23 + IF(C24="Entrada", G24, -G24) -> 6603.2
A25: 46207 | B25: Freelancer | C25: Saída | D25: Freelancer | E25: Caixa | F25: Dinheiro | G25: 150 | J25: =TEXT(A25,"yyyy-mm") -> yyyy-07 | K25: =K24 + IF(C25="Entrada", G25, -G25) -> 6453.2
A26: 46208 | B26: Vendas | C26: Entrada | D26: Vendas | G26: 4084 | J26: =TEXT(A26,"yyyy-mm") -> yyyy-07 | K26: =K25 + IF(C26="Entrada", G26, -G26) -> 10537.2
A27: 46208 | B27: Vendas Ifood | C27: Entrada | D27: Vendas iFood | E27: Banco Principal | G27: 394 | J27: =TEXT(A27,"yyyy-mm") -> yyyy-07 | K27: =K26 + IF(C27="Entrada", G27, -G27) -> 10931.2
A28: 46208 | B28: Motoby | C28: Saída | D28: iFood | E28: Banco Principal | F28: Pix | G28: 35 | J28: =TEXT(A28,"yyyy-mm") -> yyyy-07 | K28: =K27 + IF(C28="Entrada", G28, -G28) -> 10896.2
A29: 46208 | B29: Freelancer | C29: Saída | D29: Freelancer | E29: Caixa | F29: Dinheiro | G29: 150 | J29: =TEXT(A29,"yyyy-mm") -> yyyy-07 | K29: =K28 + IF(C29="Entrada", G29, -G29) -> 10746.2
A30: 46209 | B30: Vendas | C30: Entrada | D30: Vendas | G30: 1513 | J30: =TEXT(A30,"yyyy-mm") -> yyyy-07 | K30: =K29 + IF(C30="Entrada", G30, -G30) -> 12259.2
A31: 46209 | B31: Vendas Ifood | C31: Entrada | D31: Vendas iFood | E31: Banco Principal | G31: 151 | J31: =TEXT(A31,"yyyy-mm") -> yyyy-07 | K31: =K30 + IF(C31="Entrada", G31, -G31) -> 12410.2
A32: 46209 | B32: Motoboy | C32: Saída | D32: iFood | E32: Banco Principal | F32: Pix | G32: 18 | J32: =TEXT(A32,"yyyy-mm") -> yyyy-07 | K32: =K31 + IF(C32="Entrada", G32, -G32) -> 12392.2
A33: 46207 | B33: Extra Nathalia (já tinha pago, mandei pra conta Tais) | C33: Saída | D33: Freelancer | E33: Banco Principal | F33: Pix | G33: 300 | J33: =TEXT(A33,"yyyy-mm") -> yyyy-07 | K33: =K32 + IF(C33="Entrada", G33, -G33) -> 12092.2
A34: 46208 | B34: Croissant | C34: Saída | D34: Matéria Prima | E34: Banco Principal | F34: Pix | G34: 225 | J34: =TEXT(A34,"yyyy-mm") -> yyyy-07 | K34: =K33 + IF(C34="Entrada", G34, -G34) -> 11867.2
A35: 46209 | B35: Aluguel | C35: Saída | D35: CustoFixo | E35: Banco Principal | G35: 8918.64 | J35: =TEXT(A35,"yyyy-mm") -> yyyy-07 | K35: =K34 + IF(C35="Entrada", G35, -G35) -> 2948.56
A36: 46209 | B36: Iptu | C36: Saída | D36: CustoFixo | E36: Banco Principal | F36: Pix | G36: 94.9 | J36: =TEXT(A36,"yyyy-mm") -> yyyy-07 | K36: =K35 + IF(C36="Entrada", G36, -G36) -> 2853.66
A37: 46209 | B37: Alarme | C37: Saída | D37: CustoFixo | E37: Banco Principal | G37: 100 | J37: =TEXT(A37,"yyyy-mm") -> yyyy-07 | K37: =K36 + IF(C37="Entrada", G37, -G37) -> 2753.66
A38: 46209 | B38: Polar | C38: Saída | D38: Matéria Prima | E38: Banco Principal | G38: 177.86 | J38: =TEXT(A38,"yyyy-mm") -> yyyy-07 | K38: =K37 + IF(C38="Entrada", G38, -G38) -> 2575.8
A39: 46209 | B39: Polar | C39: Saída | D39: Matéria Prima | E39: Banco Principal | G39: 321.07 | J39: =TEXT(A39,"yyyy-mm") -> yyyy-07 | K39: =K38 + IF(C39="Entrada", G39, -G39) -> 2254.73
A40: 46210 | B40: Riber | C40: Saída | D40: Matéria Prima | E40: Banco Principal | G40: 529.5 | J40: =TEXT(A40,"yyyy-mm") -> yyyy-07 | K40: =K39 + IF(C40="Entrada", G40, -G40) -> 1725.23
...

Sheet Detalhado
A1: Visão geral
A3: Entradas | B3: =SUMIF(Lançamentos!C:C,"Entrada",Lançamentos!G:G) -> 76707
A4: Saídas | B4: =SUMIF(Lançamentos!C:C,"Saída",Lançamentos!G:G) -> 61836.2
A5: Saldo | B5: =B3-B4 -> 14870.8
A7: Mês | B7: Entradas no mês | C7: Saídas no mês | D7: Saldo no mês | E7: NOVEMBRO
A8: 2025-11 | B8: 133749.59 | C8: 99338.32 | D8: 34411.27
A9: Vendas | B9: 128337.2
A10: Vendas - IFood | B10: 5470.79
A11: Salario | C11: 20849.99
A12: Custo FIxo | C12: 10960.75
A13: Impostos | C13: 13106.57
A14: Materia Prima | C14: 32119.4
A15: Frete | C15: 736.52
A16: Cartão de Crédito | C16: 4478.19
A17: Mat Consumo | C17: 4744.17
A18: iFood - Moto | C18: 880
A19: Contabilidade | C19: 730
A20: Demissão | C20: 3260.25
A21: Royalt | C21: 7726.31
A22: Papelaria | C22: 3.5
... A24: Marketing | C24: 2000
A25: TOTAL | B25: 133807.99 | C25: 102839.15
A27: Mês | B27: Entradas no mês | C27: Saídas no mês | D27: Saldo no mês | E27: DEZEMBRO
A28: 2025-12 | B28: 178658.54 | C28: 118968.96 | D28: 59689.58
A29: Vendas | B29: 150151.29
A30: Vendas - IFood | B30: 4338.8
A31: Salario | C31: 26328.02
A32: Custo FIxo | C32: 15407.56
A33: Impostos | C33: 14160.93
A34: Materia Prima | C34: 47686.14
A35: Frete | C35: 0
A36: Cartão de Crédito | C36: 3898.85
A37: Mat Consumo | C37: 387.65
A38: iFood - Moto | C38: 724
A39: Contabilidade | C39: 1166.74
A40: Demissão | C40: 0
A41: Royalt | C41: 8013.92
A42: Papelaria | C42: 0
... A45: Marketing | C45: 2650
A46: TOTAL | B46: =SUM(B29:B45) -> 154490.09 | C46: =SUM(C29:C45) -> 134699.81
...

Sheet Estoque
A1: Categoria | B1: Item | C1: Qt | E1: Categoria | F1: Item | G1: Qt | I1: Categoria | J1: Item | K1: Qt | M1: Categoria | N1: Item | O1: Qt | P1: Obs
A2: Produção | B2: Acucar mascavo | C2: 1.5
A3: Produção | B3: Açúcar invertido | C3: 3 | E3: Prod Atendimento | F3: Agua c/ gás | I3: Supermercado | J3: Açúcar confeiteiro | K3: 4 | M3: Embalagens | N3: Copo G | O3: 3 | P3: fechados
A4: Produção | B4: Amarena | C4: 0 | E4: Prod Atendimento | F4: Água sem gás | I4: Supermercado | J4: Açúcar cristal | K4: 7 | M4: Embalagens | N4: Copo G | O4: 1 | P4: em uso
A5: Produção | B5: Amêndoa | C5: 1 | E5: Prod Atendimento | F5: Café | G5: 15 | I5: Supermercado | J5: Açúcar refinado | K5: 21 | M5: Embalagens | N5: Copo M | O5: 2 | P5: fechados
A6: Produção | B6: Avelã grao | C6: 1 | E6: Prod Atendimento | F6: Canudo | G6: 1 pacote | I6: Supermercado | J6: Creme de leite caixinha | K6: 19 | M6: Embalagens | N6: Copo M | O6: 1 | P6: em uso
A7: Produção | B7: Base 6 | C7: 5 | E7: Prod Atendimento | F7: Desmoldante | G7: 2 | I7: Supermercado | J7: Leite de coco | K7: 35 | M7: Embalagens | N7: Copo P | O7: 3 | P7: fechados
A8: Produção | B8: Base fruta Milk free | C8: 3 | E8: Prod Atendimento | F8: Gás sifão | G8: 3 | I8: Supermercado | J8: Óleo | K8: 11 | M8: Embalagens | N8: Copo P | O8: 1 | P8: em uso
A9: Produção | B9: Base G creme | C9: 49 | E9: Prod Atendimento | F9: Guardanapo | G9: 4 | I9: Supermercado | J9: Sal | K9: 3 | M9: Embalagens | N9: Delivery 0,5 litro | O9: 1 | P9: caixa em uso
A10: Produção | B10: Base G fruta | C10: 26 | E10: Prod Atendimento | F10: Guardanapo | G10: 1 em uso | I10: Supermercado | J10: Farinha de trigo | K10: 1 | M10: Embalagens | N10: Delivery 0,5 litro | O10: 0 | P10: fechada
A11: Produção | B11: Bombom Mescla | C11: 0
A12: Produção | B12: Bombom Pasta | C12: 0
A13: Produção | B13: Baunilha Franch | C13: 1 | E13: Prod Atendimento | F13: Nutella | G13: 3 | M13: Embalagens | N13: Delivery 0,80 ml | O13: 1 | P13: caixa em uso
A14: Produção | B14: Brunela Caramelo | C14: 0
A15: Produção | B15: Cacau Vermelho | C15: 1
A16: Produção | B16: Blend | C16: 9 | E16: Prod Atendimento | F16: Paçoquita | G16: 1 | M16: Embalagens | N16: Delivery 1 litro | O16: 1 | P16: caixa em uso
A17: Produção | B17: Canela | C17: 1 | E17: Prod Atendimento | F17: Pazinha degustação | M17: Embalagens | N17: Delivery 1 litro | O17: 1 | P17: fechada
A18: Produção | B18: Caramelo Salgado pó | C18: 0 | E18: Prod Atendimento | F18: Pazinha degustação | M18: Embalagens | N18: Delivery 180 ml | O18: 1 | P18: caixa em uso
A19: Produção | B19: Caramelo salgado crispy | C19: 0 | E19: Prod Atendimento | F19: Pazinha gelato | M19: Embalagens | N19: Delivery 300 ml | O19: 1 | P19: caixa em uso
A20: Produção | B20: Castanha de caju | C20: 1 | E20: Prod Atendimento | F20: Pazinha gelato | M20: Embalagens | N20: Sacola maior | O20: 8
A21: Produção | B21: Choc branco | C21: 1 | E21: Prod Atendimento | F21: Creme Chantilly | M21: Embalagens | N21: Sacola menor | O21: 6
A22: Produção | B22: Choc 70% | C22: 1
A23: Produção | B23: Choc 70% Nero | C23: 1 | M23: Embalagens
A24: Produção | B24: Choc meio amargo | C24: 1
A25: Produção | B25: Creme cheesecake | C25: 0
A26: Produção | B26: Crock Dubai | C26: 0
A27: Produção | B27: Creme Noce | C27: 3
A28: Produção | B28: Coco
A29: Produção | B29: Creme pistache diamante | C29: 1
A30: Produção | B30: Doce de leite | C30: 8
A31: Produção | B31: Fecula | C31: 1.5
A32: Produção | B32: Fibra Plus | C32: 3
A33: Produção | B33: Fikissimo | C33: 0
A34: Produção | B34: Fior di Arancia | C34: 1
A35: Produção | B35: Fio di bosco | C35: 3
A36: Produção | B36: Fio di maracujá | C36: 0
A37: Produção | B37: Gianduia | C37: 2
A38: Produção | B38: Glucose | C38: 2
A39: Produção | B39: La Cubaneira | C39: 2
A40: Produção | B40: Iogumix | C40: 2
...

Sheet Cartão Crédito
A1: Cartão Crédito
A3: Data | B3: Valor | C3: Descrição | E3: Total Nov
A4: 46024 | B4: 33.23 | C4: Gancho para corda | E4: =SUM(B4:B61) -> 6889.94
A5: 46025 | B5: 73.69 | C5: Abc (acucar fino + oleo)
A6: 46024 | B6: 114.12 | C6: Abc (saco de lixo)
A7: 46028 | B7: 16 | C7: Pilha
A8: 46028 | B8: 2.9 | C8: Papelaria- Clipe
A9: 46028 | B9: 39.54 | C9: Bodevan
A10: 46028 | B10: 131.13 | C10: Abc
A11: 46028 | B11: 319.54 | C11: Shop ( delivery e tapetinho)
A12: 45664 | B12: 103.15 | C12: Abc
A13: 46030 | B13: 243.48 | C13: Abc
A14: 46357 | B14: 99.27 | C14: Abc
A15: 46034 | B15: 99.34 | C15: Abc
A16: 46035 | B16: 330.64 | C16: Abc
... A30: 46050 | B30: 120.41 | C30: Abc
A32: 46052 | B32: 48.76 | C32: Copinhos na shop | D32: Cartão novo nubank.
A33: 46052 | B33: 91.53 | C33: Abc
A34: 46055 | B34: 328.49 | C34: Abc
A35: 46058 | C35: Tiarinhas carnaval
A36: 46058 | B36: 90.65 | C36: Copinhos shop
A37: 46058 | B37: 12.98 | C37: Bandaid
A38: 46059 | B38: 184.42 | C38: Caixas p bolachinhas e cascões
A39: 46062 | B39: 76.5 | C39: Lâmpadas varal deck
A40: 46063 | B40: 229.81 | C40: Abc
A41: 46064 | B41: 54.9 | C41: Pinga Doces Da Vovo
A42: 46064 | B42: 47 | C42: Amendoim
A43: 46065 | B43: 30 | C43: Trem pro carnaval
A44: 46065 | B44: 58.6 | C44: Ferramenta p cascata
A45: 46065 | B45: 44 | C45: Enfeite carnaval
A46: 46069 | B46: 285.75 | C46: Bodevan (papel toalha e higienico)
A47: 46069 | C47: Amendoim
A48: 46069 | B48: 171.16 | C48: Leite
A49: 46073 | B49: 45.9 | C49: Caixinha funcionários
A50: 46073 | B50: 60.23 | C50: Pote delivery shop
A51: 46074 | B51: 29.9 | C51: Abc, desintupidor
A52: 46075 | B52: 219.45 | C52: abc, compras
A53: 46076 | B53: 329.42 | C53: Fonte led
A54: 46076 | B54: 166.5 | C54: Papelaria
A55: 46079 | B55: 201.84 | C55: Abc
...

Sheet Boletos Futuros
B1: Março | F1: Abril | J1: Maio | N1: Junho | R1: Julho | V1: Agosto | Z1: Setembro | AD1: Outubro | AH1: Novembro | AL1: Dezembro | AP1: Janeiro_2027
B2: Data | C2: Descrição | D2: Valor | F2: Data | G2: Descrição | H2: Valor | J2: Data | K2: Descrição | L2: Valor | N2: Data | O2: Descrição | P2: Valor | R2: Data | S2: Descrição | T2: Valor | V2: Data | W2: Descrição | X2: Valor | Z2: Data | AA2: Descrição | AB2: Valor | AD2: Data | AE2: Descrição | AF2: Valor | AH2: Data | AI2: Descrição | AJ2: Valor | AL2: Data | AM2: Descrição | AN2: Valor | AP2: Data | AQ2: Descrição | AR2: Valor
B3: 5 | C3: Alarme | D3: 100 | F3: 2 | G3: Diniz | H3: 484.05 | J3: 5 | K3: Riber | L3: 1029.4 | N3: 2 | O3: Riber | P3: 477.68 | R3: 6 | S3: Polar | T3: 177.86 | V3: 4 | W3: Mec 3 | X3: 1561.18 | Z3: 30 | AA3: Tortelli | AB3: 13185 | AD3: 31 | AE3: Tortelli | AF3: 13185 | AH3: 30 | AI3: Tortelli | AJ3: 8185
B4: 9 | C4: Mec 3 | D4: 1736.83 | F4: 7 | G4: Guardanapos | H4: 537 | J4: 5 | K4: Riber | L4: 156.7 | N4: 2 | O4: Diniz | P4: 182.54 | R4: 6 | S4: Polar | T4: 321.07 | V4: 18 | W4: Mec 3 | X4: 1561.64
B5: 10 | C5: Diniz | D5: 400.39 | F5: 7 | G5: Riber | H5: 1074 | J5: 5 | K5: Riber | L5: 564.36 | N5: 3 | O5: Ecila | P5: 115.8 | R5: 1 | S5: Ecila | T5: 115.8 | V5: 3 | W5: Polar | X5: 211.23
B6: 10 | C6: Diniz | D6: 400.39 | F6: 7 | G6: Riber | H6: 1708.78 | J6: 7 | K6: Diniz | L6: 600.69 | N6: 6 | O6: Guardanapos | P6: 571.9 | R6: 14 | S6: Diniz | T6: 217.35 | V6: 31 | W6: Tortelli | X6: 13185
B7: 10 | C7: Frete mec 3 | D7: 432.89 | F7: 7 | G7: Diniz | H7: 399.72 | J7: 11 | K7: Unigra | L7: 1022.53 | N7: 8 | O7: MEC 3 | P7: 1486.49 | R7: 14 | S7: Diniz | T7: 379.7 | V7: 4 | W7: Diniz | X7: 831.47
B8: 15 | C8: Boleto odontológico | D8: 202.8 | F8: 8 | G8: Ecila | H8: 755 | J8: 11 | K8: MEC 3 | L8: 1734.28 | N8: 8 | O8: Polar | P8: 772.73 | R8: 7 | S8: Riber | T8: 529.5
B9: 17 | C9: Unigra | D9: 883.32 | F9: 11 | G9: Unigra | H9: 1022.5 | J9: 11 | K9: Polar | L9: 211.23 | N9: 8 | O9: Polar | P9: 444.67 | R9: 21 | S9: Mec 3 | T9: 1561.18
B10: 17 | C10: Riber | D10: 2521.74 | F10: 13 | G10: Castanha | H10: 850.5 | J10: 11 | K10: Polar | L10: 66.73 | N10: 9 | O10: Diniz | P10: 182.55 | R10: 14 | S10: Riber | T10: 852.89
B11: 18 | C11: Ecila | D11: 650 | F11: 13 | G11: Unigra | H11: 5052.07 | J11: 12 | K11: Riber | L11: 156.7 | N11: 9 | O11: Riber | P11: 578 | R11: 22 | S11: Ecila | T11: 738.6
B12: 18 | C12: Morango | D12: 278 | F12: 14 | G12: Riber | H12: 1708.19 | J12: 12 | K12: Riber | L12: 564.37 | N12: 9 | O12: Riber | P12: 1084.28 | R12: 25 | S12: Ecad | T12: 112.62
B13: 20 | C13: ICMS | D13: 1769.9 | F13: 15 | G13: Diniz | H13: 255.67 | J13: 12 | K13: Diniz | L13: 1977.87 | N13: 10 | O13: 1/3 unigra | P13: 1085.93 | R13: 22 | S13: Diniz | T13: 904.82
B14: 21 | C14: Pregel | D14: 329.39 | F14: 20 | G14: Pregel | H14: 329.39 | J14: 14 | K14: Andaluz | L14: 1132.95 | N14: 15 | O14: Diniz | P14: 231.55 | R14: 31 | S14: Tortelli | T14: 13185
B15: 20 | C15: DARF | D15: 724.51 | F15: 20 | G15: Riber | H15: 278.93 | J15: 14 | K15: Frutas | L15: 254.8 | N15: 16 | O15: Riber | P15: 578 | R15: 21 | S15: Riber | T15: 486.52
B16: 23 | C16: Mec 3 | D16: 1737.35 | F16: 21 | G16: Riber | H16: 1708.19 | J16: 14 | K16: Diniz(Thales) | L16: 697.1 | N16: 16 | O16: Riber | P16: 1084.28
B17: 25 | C17: Mec 3 | D17: 1139.44 | F17: 25 | G17: Polar | H17: 422.46 | J17: 18 | K17: Riber | L17: 1812.07 | N17: 16 | O17: Polar | P17: 136.51
F18: 25 | G18: Polar | H18: 1545.5 | J18: 20 | K18: Ecila (+ Thales) | L18: 115.8 | N18: 20 | O18: Guardanapos | P18: 537
B19: 30 | C19: Sistema | D19: 370 | F19: 27 | G19: Riber | H19: 278.93 | J19: 21 | K19: Diniz(Thales) | L19: 697.1 | N19: 22 | O19: MEC 3 | P19: 1486.94
B20: 30 | C20: Tráfego pago | D20: 600 | F20: 27 | G20: MEC 3 | H20: 1734.28 | J20: 25 | K20: MEC 3 | L20: 1734.8 | N20: 22 | O20: Riber | P20: 428.45
B21: 30 | C21: Polar | D21: 211.23 | F21: 28 | G21: Riber | H21: 1029.4 | J21: 25 | K21: Riber | L21: 1812.08 | N21: 23 | O21: Polar | P21: 136.51
B22: 30 | C22: Polar | D22: 416.99 | F22: 28 | G22: Diniz | H22: 326.1 | J22: 25 | K22: Polar | L22: 134.99 | N22: 29 | O22: Unigra | P22: 4817.19
B23: 31 | C23: Riber | D23: 308.15 | F23: 29 | G23: Ecila | H23: 1370 | J23: 25 | K23: Polar | L23: 222.34 | N23: 29 | O23: Riber | P23: 428.45
B24: 31 | C24: Riber | D24: 2664 | F24: 30 | G24: ICMS | H24: 389.48 | J24: 25 | K24: MEC 3 | L24: 1486.49 | N24: 29 | O24: Andaluz | P24: 1443.71
B25: 20 | C25: FGTS | D25: 767.67 | F25: 30 | G25: Unigra | H25: 4817.04 | J25: 26 | K25: Riber | L25: 477.68 | N25: 30 | O25: Polar | P25: 136.51
B26: 20 | C26: Simples | D26: 7323.66 | J26: 26 | K26: Diniz | L26: 182.54 | N26: 30 | O26: Diniz | P26: 225.27
J27: 27 | K27: Ecila | L27: 1400
J28: 28 | K28: Diniz(Thales) | L28: 697.1
J29: 30 | K29: Unigra | L29: 4817.04
B50: TOTAL | D50: =SUM(D3:D49) -> 25968.65 | F50: TOTAL | H50: =SUM(H3:H49) -> 28077.18 | J50: TOTAL | L50: =SUM(L3:L49) -> 25759.74 | N50: TOTAL | P50: =SUM(P3:P49) -> 18652.94 | R50: TOTAL | T50: =SUM(T3:T49) -> 19582.91 | V50: TOTAL | X50: =SUM(X3:X49) -> 17350.52 | Z50: TOTAL | AB50: =SUM(AB3:AB49) -> 13185 | AD50: TOTAL | AF50: =SUM(AF3:AF49) -> 13185 | AH50: TOTAL | AJ50: =SUM(AJ3:AJ49) -> 8185 | AL50: TOTAL | AN50: =SUM(AN3:AN49) -> 0 | AP50: TOTAL | AR50: =SUM(AR3:AR49) -> 0

Sheet NOV_25
K1: 0
A2: 45962 | B2: Venda de produto | C2: Entrada | D2: Vendas | E2: Banco Principal | G2: 7834 | J2: 2025-11 | K2: 7834
A3: 45962 | B3: IFood | C3: Entrada | D3: Vendas iFood | E3: Banco Principal | G3: 370 | J3: 2025-11 | K3: 8204
A4: 45962 | B4: Motoboy | C4: Saída | D4: iFood | E4: Banco Principal | F4: Pix | G4: 53 | J4: 2025-11 | K4: 8151
A5: 45963 | B5: Venda de produto | C5: Entrada | D5: Vendas | E5: Banco Principal | G5: 3000 | J5: 2025-11 | K5: 11151
A6: 45963 | B6: IFood | C6: Entrada | D6: Vendas iFood | E6: Banco Principal | G6: 441 | J6: 2025-11 | K6: 11592
A7: 45963 | B7: Motoboy | C7: Saída | D7: iFood | E7: Banco Principal | F7: Pix | G7: 54 | J7: 2025-11 | K7: 11538
A8: 45963 | B8: Boleto Unigra | C8: Saída | D8: Matéria Prima | E8: Banco Principal | G8: 772.79 | J8: 2025-11 | K8: 10765.21
A9: 45964 | B9: Luz e água mês 10 | C9: Saída | D9: CustoFixo | E9: Caixa | F9: Dinheiro | G9: 1670 | I9: Inteirar luz e água mês 10 | J9: 2025-11 | K9: 9095.21
A10: 45964 | B10: Venda de produtos | C10: Entrada | D10: Vendas | E10: Banco Principal | G10: 1708 | J10: 2025-11 | K10: 10803.21
A11: 45965 | B11: Boleto | C11: Saída | D11: Matéria Prima | E11: Banco Principal | G11: 953.18 | J11: 2025-11 | K11: 9850.03
A12: 45965 | B12: Boleto | C12: Saída | D12: Matéria Prima | E12: Banco Principal | G12: 22.12 | J12: 2025-11 | K12: 9827.91
A13: 45965 | B13: Boleto | C13: Saída | D13: Matéria Prima | E13: Banco Principal | G13: 1445.77 | J13: 2025-11 | K13: 8382.14
A14: 45965 | B14: Vale alimentação | C14: Saída | D14: Salário | E14: Banco Principal | G14: 400 | J14: 2025-11 | K14: 7982.14
A15: 45965 | B15: Impressão PAPELARIA | C15: Saída | D15: Papelaria | E15: Banco Principal | F15: Pix | G15: 3.5 | I15: Impressão Holerite | J15: 2025-11 | K15: 7978.64
A16: 45965 | B16: Leite | C16: Saída | D16: Matéria Prima | E16: Caixa | F16: Dinheiro | G16: 94 | J16: 2025-11 | K16: 7884.64
A17: 45965 | B17: Motoboy | C17: Saída | D17: iFood | E17: Banco Principal | F17: Pix | G17: 9 | J17: 2025-11 | K17: 7875.64
A18: 45965 | B18: Vendas | C18: Entrada | D18: Vendas | E18: Banco Principal | G18: 1499 | J18: 2025-11 | K18: 9374.64
A19: 45965 | B19: IFood | C19: Entrada | D19: Vendas iFood | E19: Banco Principal | G19: 78 | J19: 2025-11 | K19: 9452.64
A20: 45966 | B20: Boleto alarme | C20: Saída | D20: CustoFixo | E20: Banco Principal | G20: 100 | J20: 2025-11 | K20: 9352.64
A21: 45966 | B21: Aluguel | C21: Saída | D21: CustoFixo | E21: Banco Principal | G21: 9000 | J21: 2025-11 | K21: 352.64
A22: 45966 | B22: IPTU | C22: Saída | D22: CustoFixo | E22: Banco Principal | G22: 90.85 | J22: 2025-11 | K22: 261.79
A23: 45966 | B23: Boleto fruta congelada | C23: Saída | D23: Matéria Prima | E23: Banco Principal | G23: 278 | J23: 2025-11 | K23: -16.21
A24: 45966 | B24: Exame demissional | C24: Saída | D24: Contabilidade | E24: Banco Principal | F24: Pix | G24: 45 | I24: Exame demissional Adriana | J24: 2025-11 | K24: -61.21
A25: 45966 | B25: Leite | C25: Saída | D25: Matéria Prima | E25: Caixa | F25: Dinheiro | G25: 94 | J25: 2025-11 | K25: -155.21
A26: 45966 | B26: Carrão de crédito | C26: Saída | D26: Cartao de Credito | E26: Banco Principal | G26: 4478.19 | I26: Tudo que compro no crédito | J26: 2025-11 | K26: -4633.4
A27: 45966 | B27: Tráfego pago | C27: Saída | D27: Marketing | E27: Banco Principal | G27: 2000 | I27: Estava no cartão de crédito | J27: 2025-11 | K27: -6633.4
A28: 45966 | B28: Motoboy | C28: Saída | D28: iFood | E28: Banco Principal | F28: Pix | G28: 27 | J28: 2025-11 | K28: -6660.4
A29: 45966 | B29: Vendas do dia | C29: Entrada | D29: Vendas | G29: 1225 | J29: 2025-11 | K29: -5435.4
A30: 45966 | B30: IFood vendas | C30: Entrada | D30: Vendas iFood | E30: Banco Principal | G30: 185.2 | J30: 2025-11 | K30: -5250.2
A31: 45967 | B31: Leite | C31: Saída | D31: Matéria Prima | E31: Caixa | F31: Dinheiro | G31: 235 | J31: 2025-11 | K31: -5485.2
A32: 45967 | B32: Cubas | C32: Saída | D32: Salário | E32: Caixa | F32: Dinheiro | G32: 190 | I32: Paguei a Cubas | J32: 2025-11 | K32: -5675.2
A33: 45967 | B33: Vendas do dia | C33: Entrada | D33: Vendas | G33: 2605 | J33: 2025-11 | K33: -3070.2
A34: 45967 | B34: IFood vendas | C34: Entrada | D34: Vendas iFood | E34: Banco Principal | G34: 58.4 | J34: 2025-11 | K34: -3011.8
A35: 45967 | B35: Motoboy | C35: Saída | D35: iFood | E35: Banco Principal | F35: Pix | G35: 9 | J35: 2025-11 | K35: -3020.8
A36: 45968 | B36: Salários | C36: Saída | D36: Salário | E36: Banco Principal | F36: Pix | G36: 9642.93 | J36: 2025-11 | K36: -12663.73
A37: 45968 | B37: Leite | C37: Saída | D37: Matéria Prima | E37: Caixa | F37: Dinheiro | G37: 376 | J37: 2025-11 | K37: -13039.73
A38: 45968 | B38: Motoboy | C38: Saída | D38: iFood | E38: Banco Principal | F38: Pix | G38: 35 | J38: 2025-11 | K38: -13074.73
A39: 45968 | B39: Vendas do dia | C39: Entrada | D39: Vendas | G39: 3432.3 | J39: 2025-11 | K39: -9642.43
A40: 45968 | B40: Vendas iFood | C40: Entrada | D40: Vendas iFood | E40: Banco Principal | G40: 302.5 | J40: 2025-11 | K40: -9339.93
...

Sheet DEZ_25
A2: 45992 | B2: Caixa_Novembro_25 | C2: Entrada | D2: Caixa_mes_anterior | G2: 30968.84 | I2: Caixa_mes_anterior | J2: 2025-12 | K2: 30968.84
A3: 45992 | B3: Vale alimentação | C3: Saída | D3: Salário | E3: Banco Principal | G3: 2400 | J3: 2025-12 | K3: 28568.84
A4: 45992 | B4: Boleto sistema | C4: Saída | D4: CustoFixo | E4: Banco Principal | G4: 370 | J4: 2025-12 | K4: 28198.84
A5: 45992 | B5: Leite | C5: Saída | D5: Matéria Prima | E5: Caixa | F5: Dinheiro | G5: 235 | J5: 2025-12 | K5: 27963.84
A6: 45992 | B6: Peça da máquina produtora | C6: Saída | D6: Mat Consumo | E6: Banco Principal | F6: Pix | G6: 160 | J6: 2025-12 | K6: 27803.84
A7: 45992 | B7: Água | C7: Saída | D7: Matéria Prima | E7: Banco Principal | F7: Pix | G7: 203.5 | J7: 2025-12 | K7: 27600.34
A8: 45992 | B8: Tráfego Pago | C8: Saída | D8: Marketing | E8: Banco Principal | F8: Pix | G8: 600 | J8: 2025-12 | K8: 27000.34
A9: 45992 | B9: Tortelli | C9: Saída | D9: Tortelli | E9: Banco Principal | G9: 13185 | J9: 2025-12 | K9: 13815.34
A10: 45992 | B10: Vendas do dia | C10: Entrada | D10: Vendas | G10: 1824 | J10: 2025-12 | K10: 15639.34
A11: 45992 | B11: Motoboy | C11: Saída | D11: iFood | E11: Banco Principal | F11: Pix | G11: 19 | J11: 2025-12 | K11: 15620.34
A12: 45993 | B12: Boleto Ecila | C12: Saída | D12: Matéria Prima | E12: Banco Principal | G12: 767.37 | J12: 2025-12 | K12: 14852.97
A13: 45993 | B13: Boleto Mec 3 | C13: Saída | D13: Matéria Prima | E13: Banco Principal | G13: 1341.23 | J13: 2025-12 | K13: 13511.74
A14: 45993 | B14: Creme de Leite | C14: Saída | D14: Matéria Prima | E14: Banco Principal | F14: Pix | G14: 698 | J14: 2025-12 | K14: 12813.74
A15: 45993 | B15: Boleto Riber | C15: Saída | D15: Matéria Prima | E15: Banco Principal | G15: 399.94 | J15: 2025-12 | K15: 12413.8
A16: 45993 | B16: Supermercado | C16: Saída | D16: Matéria Prima | E16: Banco Principal | F16: Pix | G16: 100 | J16: 2025-12 | K16: 12313.8
A17: 45993 | B17: Vendas do dia | C17: Entrada | D17: Vendas | G17: 952 | J17: 2025-12 | K17: 13265.8
A18: 45993 | B18: Vendas iFood | C18: Entrada | D18: Vendas iFood | E18: Banco Principal | G18: 200.39 | J18: 2025-12 | K18: 13466.19
A19: 45993 | B19: Motoboy | C19: Saída | D19: iFood | E19: Banco Principal | F19: Pix | G19: 25 | J19: 2025-12 | K19: 13441.19
A20: 45994 | B20: Leite | C20: Saída | D20: Matéria Prima | E20: Caixa | F20: Dinheiro | G20: 0 | J20: 2025-12 | K20: 13441.19
A21: 45994 | B21: Boleto Unigra | C21: Saída | D21: Matéria Prima | E21: Banco Principal | G21: 772.82 | J21: 2025-12 | K21: 12668.37
A22: 45994 | B22: Impressão holerite | C22: Saída | D22: Salário | E22: Banco Principal | F22: Pix | G22: 3 | J22: 2025-12 | K22: 12665.37
A23: 45994 | B23: Vendas do dia | C23: Entrada | D23: Vendas | G23: 1599 | J23: 2025-12 | K23: 14264.37
A24: 45994 | B24: Vendas iFood | C24: Entrada | D24: Vendas iFood | E24: Banco Principal | G24: 117 | J24: 2025-12 | K24: 14381.37
A25: 45995 | B25: Boleto Mec 3 | C25: Saída | D25: Matéria Prima | E25: Banco Principal | G25: 1360.97 | J25: 2025-12 | K25: 13020.4
A26: 45995 | B26: Boleto Alarme | C26: Saída | D26: CustoFixo | E26: Banco Principal | G26: 100 | J26: 2025-12 | K26: 12920.4
A27: 45995 | B27: Leite | C27: Saída | D27: Matéria Prima | E27: Caixa | F27: Dinheiro | G27: 282 | J27: 2025-12 | K27: 12638.4
A28: 45995 | B28: Vendas do dia | C28: Entrada | D28: Vendas | G28: 1795 | J28: 2025-12 | K28: 14433.4
A29: 45995 | B29: Venda Ifood | C29: Entrada | D29: Vendas iFood | E29: Banco Principal | G29: 0 | J29: 2025-12 | K29: 14433.4
A30: 45996 | B30: Salario Pessoal | C30: Saída | D30: Salário | E30: Banco Principal | G30: 9432.18 | J30: 2025-12 | K30: 5001.22
A31: 45996 | B31: Aluguel | C31: Saída | D31: CustoFixo | E31: Banco Principal | G31: 9000 | J31: 2025-12 | K31: -3998.78
A32: 45996 | B32: IPTU | C32: Saída | D32: CustoFixo | E32: Banco Principal | G32: 90.85 | J32: 2025-12 | K32: -4089.63
A33: 45996 | B33: Cartão de credito | C33: Saída | D33: Cartao de Credito | E33: Banco Principal | G33: 3898.85 | J33: 2025-12 | K33: -7988.48
A34: 45996 | B34: Vendas do dia | C34: Entrada | D34: Vendas | G34: 3862 | J34: 2025-12 | K34: -4126.48
A35: 45996 | B35: Vendas iFood | C35: Entrada | D35: Vendas iFood | E35: Banco Principal | G35: 185.12 | J35: 2025-12 | K35: -3941.36
A36: 45996 | B36: Leite | C36: Saída | D36: Matéria Prima | E36: Caixa | F36: Dinheiro | G36: 376 | J36: 2025-12 | K36: -4317.36
A37: 45996 | B37: Moça Faxina | C37: Saída | D37: Salário | E37: Banco Principal | F37: Pix | G37: 824 | J37: 2025-12 | K37: -5141.36
A38: 45996 | B38: Restante cubas | C38: Saída | D38: Salário | E38: Caixa | F38: Dinheiro | G38: 150 | J38: 2025-12 | K38: -5291.36
A39: 45996 | B39: Motoboy | C39: Saída | D39: iFood | E39: Banco Principal | F39: Pix | G39: 27 | J39: 2025-12 | K39: -5318.36
A40: 45997 | B40: Vendas do dia | C40: Entrada | D40: Vendas | G40: 8793 | J40: 2025-12 | K40: 3474.64
A41: 45997 | B41: Vendas iFood | C41: Entrada | D41: Vendas iFood | E41: Banco Principal | G41: 400.7 | J41: 2025-12 | K41: 3875.34
...

Sheet JAN_26
A2: Data | B2: Descrição | C2: Tipo | D2: Categoria | E2: Conta | F2: Forma de pagamento | G2: Valor | I2: Obs | J2: Mês | K2: Saldo acumulado
A3: 46024 | B3: Tortelli | C3: Saída | D3: Tortelli | E3: Banco Principal | G3: 13185 | J3: 2026-01 | K3: -13185
A4: 46024 | B4: Vendas | C4: Entrada | D4: Vendas | G4: 10749 | J4: 2026-01 | K4: -2436
A5: 46024 | B5: Vendas Ifood | C5: Entrada | D5: Vendas iFood | G5: 228.9 | J5: 2026-01 | K5: -2207.1
A6: 46024 | B6: Motoboy | C6: Saída | D6: iFood | E6: Banco Principal | F6: Pix | G6: 35 | J6: 2026-01 | K6: -2242.1
A7: 46024 | B7: Leite | C7: Saída | D7: Matéria Prima | E7: Caixa | F7: Dinheiro | G7: 188 | J7: 2026-01 | K7: -2430.1
A8: 46024 | B8: Água | C8: Saída | D8: Matéria Prima | E8: Banco Principal | F8: Pix | G8: 203.5 | J8: 2026-01 | K8: -2633.6
A9: 46024 | B9: Celso Boleto | C9: Saída | D9: Celso | E9: Banco Principal | G9: 5091.58 | J9: 2026-01 | K9: -7725.18
A10: 46024 | B10: Celso Pix | C10: Saída | D10: Celso | E10: Banco Principal | F10: Pix | G10: 8462.74 | J10: 2026-01 | K10: -16187.92
A11: 46025 | B11: Leite | C11: Saída | D11: Matéria Prima | E11: Caixa | F11: Dinheiro | G11: 300 | J11: 2026-01 | K11: -16487.92
A12: 46025 | B12: Freelancer | C12: Saída | D12: Freelancer | E12: Caixa | F12: Dinheiro | G12: 150 | J12: 2026-01 | K12: -16637.92
A13: 46025 | B13: Vendas | C13: Entrada | D13: Vendas | G13: 12622 | J13: 2026-01 | K13: -4015.92
A14: 46025 | B14: Vendas Ifood | C14: Entrada | D14: Vendas iFood | E14: Banco Principal | G14: 183.15 | J14: 2026-01 | K14: -3832.77
A15: 46025 | B15: Motoboy | C15: Saída | D15: iFood | E15: Banco Principal | F15: Pix | G15: 44 | J15: 2026-01 | K15: -3876.77
A16: 46026 | B16: Leite | C16: Saída | D16: Matéria Prima | E16: Caixa | F16: Dinheiro | G16: 235 | J16: 2026-01 | K16: -4111.77
A17: 46026 | B17: Freelancer | C17: Saída | D17: Freelancer | E17: Caixa | F17: Dinheiro | G17: 270 | J17: 2026-01 | K17: -4381.77
A18: 46026 | B18: Vendas | C18: Entrada | D18: Vendas | G18: 12260 | J18: 2026-01 | K18: 7878.23
A19: 46026 | B19: Vendas Ifood | C19: Entrada | D19: Vendas iFood | E19: Banco Principal | G19: 798.02 | J19: 2026-01 | K19: 8676.25
A20: 46026 | B20: Motoboy | C20: Saída | D20: iFood | E20: Banco Principal | F20: Pix | G20: 95 | J20: 2026-01 | K20: 8581.25
A21: 46027 | B21: Boleto Potes Delivery | C21: Saída | D21: Mat Consumo | E21: Banco Principal | G21: 929.88 | J21: 2026-01 | K21: 7651.37
A22: 46027 | B22: Boleto Polar | C22: Saída | D22: Matéria Prima | E22: Banco Principal | G22: 1115.22 | J22: 2026-01 | K22: 6536.15
A23: 46027 | B23: Boleto Polar | C23: Saída | D23: Matéria Prima | E23: Banco Principal | G23: 833.98 | J23: 2026-01 | K23: 5702.17
A24: 46027 | B24: Frutas Congeladas | C24: Saída | D24: Matéria Prima | E24: Banco Principal | G24: 315 | J24: 2026-01 | K24: 5387.17
A25: 46027 | B25: Creme de Leite | C25: Saída | D25: Matéria Prima | E25: Banco Principal | G25: 646 | J25: 2026-01 | K25: 4741.17
A26: 46027 | B26: Aluguel | C26: Saída | D26: CustoFixo | E26: Banco Principal | G26: 9000 | J26: 2026-01 | K26: -4258.83
A27: 46027 | B27: Leite | C27: Saída | D27: Matéria Prima | E27: Caixa | G27: 141 | J27: 2026-01 | K27: -4399.83
A28: 46027 | B28: Vendas | C28: Entrada | D28: Vendas | G28: 4473 | J28: 2026-01 | K28: 73.17
A29: 46027 | B29: Vendas Ifood | C29: Entrada | D29: Vendas iFood | E29: Banco Principal | G29: 96.29 | J29: 2026-01 | K29: 169.46
A30: 46027 | B30: Motoboy | C30: Saída | D30: iFood | E30: Banco Principal | G30: 8 | J30: 2026-01 | K30: 161.46
A31: 46027 | B31: Cartao de Credito | C31: Saída | D31: Cartao de Credito | E31: Banco Principal | G31: 5371.8 | J31: 2026-01 | K31: -5210.34
A32: 46027 | B32: Trafego Pago | C32: Saída | D32: Marketing | E32: Banco Principal | G32: 1000 | J32: 2026-01 | K32: -6210.34
A33: 46028 | B33: Pano de Prato | C33: Saída | D33: Mat Consumo | E33: Caixa | F33: Dinheiro | G33: 20 | J33: 2026-01 | K33: -6230.34
A34: 46028 | B34: Vendas | C34: Entrada | D34: Vendas | G34: 4131 | J34: 2026-01 | K34: -2099.34
A35: 46028 | B35: Vendas Ifood | C35: Entrada | D35: Vendas iFood | E35: Banco Principal | G35: 19.6 | J35: 2026-01 | K35: -2079.74
A36: 46028 | B36: Motoboy | C36: Saída | D36: iFood | E36: Banco Principal | G36: 0 | J36: 2026-01 | K36: -2079.74
A37: 46028 | B37: Frutas Congeladas | C37: Saída | D37: Matéria Prima | E37: Banco Principal | F37: Pix | G37: 290 | J37: 2026-01 | K37: -2369.74
A38: 46028 | B38: Boleto Unigra | C38: Saída | D38: Matéria Prima | E38: Banco Principal | G38: 3208.22 | J38: 2026-01 | K38: -5577.96
A39: 46028 | B39: Boleto Guardanapo | C39: Saída | D39: Mat Consumo | E39: Banco Principal | G39: 476.59 | J39: 2026-01 | K39: -6054.55
A40: 46028 | B40: Boleto Riber | C40: Saída | D40: Matéria Prima | E40: Banco Principal | G40: 3409.49 | J40: 2026-01 | K40: -9464.04
A41: 46028 | B41: Boleto Mec3 | C41: Saída | D41: Matéria Prima | E41: Banco Principal | G41: 2269.26 | J41: 2026-01 | K41: -11733.3
...

Sheet FEV_25
A1: Data | B1: Descrição | C1: Tipo | D1: Categoria | E1: Conta | F1: Forma de pagamento | G1: Valor | I1: Obs | J1: Mês | K1: Saldo acumulado
A2: 46054 | B2: Dias Amanda teste | C2: Saída | D2: Freelancer | E2: Banco Principal | F2: Pix | G2: 390 | J2: 2026-02 | K2: -390
A3: 46054 | B3: Vendas | C3: Entrada | D3: Vendas | G3: 5836 | J3: 2026-02 | K3: 5446
A4: 46054 | B4: Vendas Ifood | C4: Entrada | D4: Vendas iFood | E4: Banco Principal | G4: 387.11 | J4: 2026-02 | K4: 5833.11
A5: 46054 | B5: Motoboy | C5: Saída | D5: iFood | E5: Banco Principal | F5: Pix | G5: 54 | J5: 2026-02 | K5: 5779.11
A6: 46055 | B6: Boleto Diniz | C6: Saída | D6: Matéria Prima | E6: Banco Principal | G6: 464.11 | J6: 2026-02 | K6: 5315
A7: 46055 | B7: ICMS | C7: Saída | D7: Impostos | E7: Banco Principal | G7: 263.86 | J7: 2026-02 | K7: 5051.14
A8: 46055 | B8: Vendas | C8: Entrada | D8: Vendas | G8: 1657 | J8: 2026-02 | K8: 6708.14
A9: 46055 | B9: Vendas iFood | C9: Entrada | D9: Vendas iFood | E9: Banco Principal | G9: 0 | J9: 2026-02 | K9: 6708.14
A10: 46055 | B10: Motoboy | C10: Saída | D10: iFood | E10: Banco Principal | F10: Pix | G10: 0 | J10: 2026-02 | K10: 6708.14
A11: 46055 | B11: Leite | C11: Saída | D11: Matéria Prima | E11: Caixa | F11: Dinheiro | G11: 0 | J11: 2026-02 | K11: 6708.14
A12: 46055 | B12: Exame adimissional | C12: Saída | D12: Contabilidade | E12: Banco Principal | F12: Pix | G12: 45 | J12: 2026-02 | K12: 6663.14
A13: 46055 | B13: Plaquinha e adesivo | C13: Saída | D13: Marketing | E13: Banco Principal | F13: Pix | G13: 45 | J13: 2026-02 | K13: 6618.14
A14: 46056 | B14: Vendas | C14: Entrada | D14: Vendas | G14: 1296 | J14: 2026-02 | K14: 7914.14
A15: 46056 | B15: Vendas Ifood | C15: Entrada | D15: Vendas iFood | E15: Banco Principal | G15: 151.79 | J15: 2026-02 | K15: 8065.93
A16: 46056 | B16: Motoboy | C16: Saída | D16: iFood | E16: Banco Principal | F16: Pix | G16: 36 | J16: 2026-02 | K16: 8029.93
A17: 46056 | B17: Leite | C17: Saída | D17: Matéria Prima | E17: Caixa | F17: Dinheiro | G17: 0 | J17: 2026-02 | K17: 8029.93
A18: 46056 | B18: Frutas | C18: Saída | D18: Matéria Prima | E18: Banco Principal | F18: Pix | G18: 455 | J18: 2026-02 | K18: 7574.93
A19: 46056 | B19: Agua | C19: Saída | D19: Matéria Prima | E19: Banco Principal | F19: Pix | G19: 203.5 | J19: 2026-02 | K19: 7371.43
A20: 46056 | B20: Boleto Ecila | C20: Saída | D20: Matéria Prima | E20: Banco Principal | G20: 708.88 | J20: 2026-02 | K20: 6662.55
A21: 46056 | B21: Boleto riber | C21: Saída | D21: Matéria Prima | E21: Banco Principal | G21: 1106.8 | J21: 2026-02 | K21: 5555.75
A22: 46056 | B22: Boleto riber | C22: Saída | D22: Matéria Prima | E22: Banco Principal | G22: 2822 | J22: 2026-02 | K22: 2733.75
A23: 46056 | B23: Boleto mec 3 | C23: Saída | D23: Matéria Prima | E23: Banco Principal | G23: 2269.94 | J23: 2026-02 | K23: 463.81
A24: 46056 | B24: Paçoca | C24: Saída | D24: Matéria Prima | E24: Caixa | F24: Dinheiro | G24: 53 | J24: 2026-02 | K24: 410.81
A25: 46057 | B25: Vendas | C25: Entrada | D25: Vendas | G25: 1846 | J25: 2026-02 | K25: 2256.81
A26: 46057 | B26: Vendas Ifood | C26: Entrada | D26: Vendas iFood | E26: Banco Principal | G26: 226.89 | J26: 2026-02 | K26: 2483.7
A27: 46057 | B27: Motoboy | C27: Saída | D27: iFood | E27: Banco Principal | F27: Pix | G27: 27 | J27: 2026-02 | K27: 2456.7
A28: 46057 | B28: Leite | C28: Saída | D28: Matéria Prima | E28: Caixa | F28: Dinheiro | G28: 235 | J28: 2026-02 | K28: 2221.7
A29: 46057 | B29: Salarios | C29: Saída | D29: Salário | E29: Banco Principal | F29: Pix | G29: 6269.02 | J29: 2026-02 | K29: -4047.32
A30: 46057 | B30: Salrio Tais | C30: Saída | D30: Salário | E30: Banco Principal | F30: Pix | G30: 4500 | J30: 2026-02 | K30: -8547.32
A31: 46058 | B31: Cartão | C31: Saída | D31: Cartao de Credito | E31: Banco Principal | G31: 4243.39 | J31: 2026-02 | K31: -12790.71
A32: 46058 | B32: Tráfego pago | C32: Saída | D32: Marketing | E32: Banco Principal | G32: 1000 | J32: 2026-02 | K32: -13790.71
A33: 46058 | B33: Aluguel | C33: Saída | D33: CustoFixo | E33: Banco Principal | G33: 9000 | J33: 2026-02 | K33: -22790.71
A34: 46058 | B34: Alarme | C34: Saída | D34: CustoFixo | E34: Banco Principal | G34: 100 | J34: 2026-02 | K34: -22890.71
A35: 46058 | B35: Leite | C35: Saída | D35: Matéria Prima | E35: Caixa | F35: Dinheiro | G35: 0 | J35: 2026-02 | K35: -22890.71
A36: 46058 | B36: Vendas | C36: Entrada | D36: Vendas | G36: 1824 | J36: 2026-02 | K36: -21066.71
A37: 46058 | B37: Venda iFood | C37: Entrada | D37: Vendas iFood | E37: Banco Principal | G37: 0 | J37: 2026-02 | K37: -21066.71
A38: 46058 | B38: Motoboy | C38: Saída | D38: iFood | E38: Banco Principal | F38: Pix | G38: 0 | J38: 2026-02 | K38: -21066.71
A39: 46058 | B39: Creme de leite | C39: Saída | D39: Matéria Prima | E39: Banco Principal | F39: Pix | G39: 594.5 | J39: 2026-02 | K39: -21661.21
A40: 46059 | B40: Leite | C40: Saída | D40: Matéria Prima | E40: Caixa | F40: Dinheiro | G40: 329 | J40: 2026-02 | K40: -21990.21
...

Sheet MAR_26
A1: Data | B1: Descrição | C1: Tipo | D1: Categoria | E1: Conta | F1: Forma de pagamento | G1: Valor | I1: Obs | J1: Mês | K1: Saldo acumulado
A2: 46082 | B2: Vendas | C2: Entrada | D2: Vendas | G2: 6466 | J2: 2026-03 | K2: 6466
A3: 46082 | B3: Vendas Ifood | C3: Entrada | D3: Vendas iFood | E3: Banco Principal | G3: 349.8 | J3: 2026-03 | K3: 6815.8
A4: 46082 | B4: Motoboy | C4: Saída | D4: iFood | E4: Banco Principal | F4: Pix | G4: 70 | J4: 2026-03 | K4: 6745.8
A5: 46083 | B5: Faxina | C5: Saída | D5: Salário | E5: Banco Principal | F5: Pix | G5: 1100 | J5: 2026-03 | K5: 5645.8
A6: 46083 | B6: Boleto polar (Thales) | C6: Saída | D6: Matéria Prima | E6: Banco Principal | G6: 822.66 | J6: 2026-03 | K6: 4823.14
A7: 46083 | B7: Vendas | C7: Entrada | D7: Vendas | G7: 961 | J7: 2026-03 | K7: 5784.14
A8: 46083 | B8: Vendas iFood | C8: Entrada | D8: Vendas iFood | E8: Banco Principal | G8: 84.7 | J8: 2026-03 | K8: 5868.84
A9: 46083 | B9: Motoboy | C9: Saída | D9: iFood | E9: Banco Principal | F9: Pix | G9: 18 | J9: 2026-03 | K9: 5850.84
A10: 46084 | B10: Vendas | C10: Entrada | D10: Vendas | G10: 1606 | J10: 2026-03 | K10: 7456.84
A11: 46084 | B11: Vendas Ifood | C11: Entrada | D11: Vendas iFood | E11: Banco Principal | G11: 187.8 | J11: 2026-03 | K11: 7644.64
A12: 46084 | B12: Motoboy | C12: Saída | D12: iFood | E12: Banco Principal | F12: Pix | G12: 19 | J12: 2026-03 | K12: 7625.64
A13: 46084 | B13: Leite | C13: Saída | D13: Matéria Prima | E13: Caixa | F13: Dinheiro | G13: 0 | J13: 2026-03 | K13: 7625.64
A14: 46084 | B14: Luz + água | C14: Saída | D14: CustoFixo | E14: Caixa | F14: Dinheiro | G14: 3435.1 | J14: 2026-03 | K14: 4190.54
A15: 46084 | B15: Boleto riber | C15: Saída | D15: Matéria Prima | E15: Banco Principal | G15: 4143.2 | J15: 2026-03 | K15: 47.34
A16: 46084 | B16: Adesivo | C16: Saída | D16: Marketing | E16: Caixa | F16: Dinheiro | G16: 15 | J16: 2026-03 | K16: 32.34
A17: 46085 | B17: Vendas | C17: Entrada | D17: Vendas | G17: 2354 | J17: 2026-03 | K17: 2386.34
A18: 46085 | B18: Vendas iFood | C18: Entrada | D18: Vendas iFood | E18: Banco Principal | G18: 68.1 | J18: 2026-03 | K18: 2454.44
A19: 46085 | B19: Motoboy | C19: Saída | D19: iFood | E19: Banco Principal | F19: Pix | G19: 18 | J19: 2026-03 | K19: 2436.44
A20: 46085 | B20: Leite | C20: Saída | D20: Matéria Prima | E20: Caixa | F20: Dinheiro | G20: 235 | J20: 2026-03 | K20: 2201.44
A21: 46085 | B21: Adesivos | C21: Saída | D21: CustoFixo | E21: Banco Principal | F21: Pix | G21: 200 | J21: 2026-03 | K21: 2001.44
A22: 46086 | B22: Aluguel | C22: Saída | D22: CustoFixo | E22: Banco Principal | G22: 8918.64 | J22: 2026-03 | K22: -6917.2
A23: 46086 | B23: IPTU | C23: Saída | D23: CustoFixo | E23: Banco Principal | F23: Pix | G23: 94.9 | J23: 2026-03 | K23: -7012.1
A24: 46086 | B24: Alarme | C24: Saída | D24: CustoFixo | E24: Banco Principal | G24: 100 | J24: 2026-03 | K24: -7112.1
A25: 46086 | B25: Cartão de crédito restante | C25: Saída | D25: Cartao de Credito | E25: Banco Principal | G25: 566.91 | J25: 2026-03 | K25: -7679.01
A26: 46086 | B26: Salários | C26: Saída | D26: Salário | E26: Banco Principal | F26: Pix | G26: 7720.45 | J26: 2026-03 | K26: -15399.46
A27: 46086 | B27: Vendas | C27: Entrada | D27: Vendas | G27: 2009 | J27: 2026-03 | K27: -13390.46
A28: 46086 | B28: Vendas iFood | C28: Entrada | D28: Vendas iFood | E28: Banco Principal | G28: 203.2 | J28: 2026-03 | K28: -13187.26
A29: 46086 | B29: Motoboy | C29: Saída | D29: iFood | E29: Banco Principal | F29: Pix | G29: 27 | J29: 2026-03 | K29: -13214.26
A30: 46086 | B30: Leite | C30: Saída | D30: Matéria Prima | E30: Caixa | F30: Dinheiro | G30: 141 | J30: 2026-03 | K30: -13355.26
A31: 46086 | B31: Salário Tais | C31: Saída | D31: Salário | E31: Banco Principal | F31: Pix | G31: 5000 | J31: 2026-03 | K31: -18355.26
A32: 46086 | B32: Restante dias Amanda | C32: Saída | D32: Salário | E32: Banco Principal | F32: Pix | G32: 162 | J32: 2026-03 | K32: -18517.26
A33: 46087 | B33: Vendas | C33: Entrada | D33: Vendas | G33: 4333 | J33: 2026-03 | K33: -14184.26
A34: 46087 | B34: Vendas Ifood | C34: Entrada | D34: Vendas iFood | E34: Banco Principal | G34: 457.8 | J34: 2026-03 | K34: -13726.46
A35: 46087 | B35: Motoboy | C35: Saída | D35: iFood | E35: Banco Principal | F35: Pix | G35: 65 | J35: 2026-03 | K35: -13791.46
A36: 46087 | B36: Leite | C36: Saída | D36: Matéria Prima | E36: Caixa | F36: Dinheiro | G36: 423 | J36: 2026-03 | K36: -14214.46
A37: 46088 | B37: Vendas | C37: Entrada | D37: Vendas | G37: 6927 | J37: 2026-03 | K37: -7287.46
A38: 46088 | B38: Vendas Ifood | C38: Entrada | D38: Vendas iFood | E38: Banco Principal | G38: 393.5 | J38: 2026-03 | K38: -6893.96
A39: 46088 | B39: Motoboy | C39: Saída | D39: iFood | E39: Banco Principal | F39: Pix | G39: 72 | J39: 2026-03 | K39: -6965.96
A40: 46089 | B40: Vendas | C40: Entrada | D40: Vendas | G40: 8788 | J40: 2026-03 | K40: 1822.04
...

Sheet ABR_26
A1: Data | B1: Descrição | C1: Tipo | D1: Categoria | E1: Conta | F1: Forma de pagamento | G1: Valor | I1: Obs | J1: Mês | K1: Saldo acumulado
A2: 46113 | B2: Vendas | C2: Entrada | D2: Vendas | G2: 3280 | J2: 2026-04 | K2: 3280
A3: 46113 | B3: Vendas Ifood | C3: Entrada | D3: Vendas iFood | E3: Banco Principal | G3: 173.6 | J3: 2026-04 | K3: 3453.6
A4: 46113 | B4: Motoboy | C4: Saída | D4: iFood | E4: Banco Principal | F4: Pix | G4: 35 | J4: 2026-04 | K4: 3418.6
A5: 46113 | B5: Leite | C5: Saída | D5: Matéria Prima | E5: Caixa | F5: Dinheiro | G5: 188 | J5: 2026-04 | K5: 3230.6
A6: 46113 | B6: Hora extra Luany | C6: Saída | D6: Freelancer | E6: Caixa | F6: Dinheiro | G6: 15 | J6: 2026-04 | K6: 3215.6
A7: 46114 | B7: Boleto Diniz | C7: Saída | D7: Matéria Prima | E7: Banco Principal | G7: 484.05 | J7: 2026-04 | K7: 2731.55
A8: 46114 | B8: Vendas | C8: Entrada | D8: Vendas | G8: 5110 | J8: 2026-04 | K8: 7841.55
A9: 46114 | B9: Vendas Ifood | C9: Entrada | D9: Vendas iFood | E9: Banco Principal | G9: 97.5 | J9: 2026-04 | K9: 7939.05
A10: 46114 | B10: Motoboy | C10: Saída | D10: iFood | E10: Banco Principal | F10: Pix | G10: 27 | J10: 2026-04 | K10: 7912.05
A11: 46114 | B11: Leite | C11: Saída | D11: Matéria Prima | E11: Caixa | F11: Dinheiro | G11: 0 | J11: 2026-04 | K11: 7912.05
A12: 46115 | B12: Vendas | C12: Entrada | D12: Vendas | G12: 7846 | J12: 2026-04 | K12: 15758.05
A13: 46115 | B13: Vendas Ifood | C13: Entrada | D13: Vendas iFood | E13: Banco Principal | G13: 219.1 | J13: 2026-04 | K13: 15977.15
A14: 46115 | B14: Motoboy | C14: Saída | D14: iFood | E14: Banco Principal | F14: Pix | G14: 36 | J14: 2026-04 | K14: 15941.15
A15: 46115 | B15: Leite | C15: Saída | D15: Matéria Prima | E15: Caixa | F15: Dinheiro | G15: 376 | J15: 2026-04 | K15: 15565.15
A16: 46116 | B16: Vendas | C16: Entrada | D16: Vendas | G16: 9776 | J16: 2026-04 | K16: 25341.15
A17: 46117 | B17: Vendas Ifood | C17: Entrada | D17: Vendas iFood | E17: Banco Principal | G17: 58.5 | J17: 2026-04 | K17: 25399.65
A18: 46118 | B18: Motoboy | C18: Saída | D18: iFood | E18: Banco Principal | F18: Pix | G18: 9 | J18: 2026-04 | K18: 25390.65
A19: 46119 | B19: Ovinhos meninas | C19: Saída | D19: Mat Consumo | E19: Caixa | F19: Dinheiro | G19: 132 | J19: 2026-04 | K19: 25258.65
A20: 46117 | B20: Vendas | C20: Entrada | D20: Vendas | G20: 5201 | J20: 2026-04 | K20: 30459.65
A21: 46117 | B21: Vendas Ifood | C21: Entrada | D21: Vendas iFood | E21: Banco Principal | G21: 123.3 | J21: 2026-04 | K21: 30582.95
A22: 46117 | B22: Motoboy | C22: Saída | D22: iFood | E22: Banco Principal | F22: Pix | G22: 27 | J22: 2026-04 | K22: 30555.95
A23: 46117 | B23: Leite | C23: Saída | D23: Matéria Prima | E23: Caixa | F23: Dinheiro | G23: 94 | J23: 2026-04 | K23: 30461.95
A24: 46118 | B24: Vendas | C24: Entrada | D24: Vendas | G24: 1472 | J24: 2026-04 | K24: 31933.95
A25: 46118 | B25: Vendas Ifood | C25: Entrada | D25: Vendas iFood | E25: Banco Principal | G25: 0 | J25: 2026-04 | K25: 31933.95
A26: 46118 | B26: Motoboy | C26: Saída | D26: iFood | E26: Banco Principal | F26: Pix | G26: 0 | J26: 2026-04 | K26: 31933.95
A27: 46118 | B27: Leite | C27: Saída | D27: Matéria Prima | E27: Caixa | F27: Dinheiro | G27: 0 | J27: 2026-04 | K27: 31933.95
A28: 46118 | B28: Aluguel | C28: Saída | D28: CustoFixo | E28: Banco Principal | G28: 8918.64 | J28: 2026-04 | K28: 23015.31
A29: 46118 | B29: IPTU | C29: Saída | D29: CustoFixo | E29: Banco Principal | F29: Pix | G29: 94.6 | J29: 2026-04 | K29: 22920.71
A30: 46118 | B30: Alarme | C30: Saída | D30: CustoFixo | E30: Banco Principal | G30: 100 | J30: 2026-04 | K30: 22820.71
A31: 46118 | B31: Pagamento Tais | C31: Saída | D31: Salário | E31: Banco Principal | F31: Pix | G31: 4000 | J31: 2026-04 | K31: 18820.71
A32: 46118 | B32: Boleto Riber | C32: Saída | D32: Matéria Prima | E32: Banco Principal | G32: 1074 | J32: 2026-04 | K32: 17746.71
A33: 46118 | B33: Boleto Riber | C33: Saída | D33: Matéria Prima | E33: Banco Principal | G33: 1708.78 | J33: 2026-04 | K33: 16037.93
A34: 46118 | B34: Boleto Diniz | C34: Saída | D34: Matéria Prima | E34: Banco Principal | G34: 399.72 | J34: 2026-04 | K34: 15638.21
A35: 46118 | B35: Boleto guardanapos | C35: Saída | D35: Mat Consumo | E35: Banco Principal | G35: 537 | J35: 2026-04 | K35: 15101.21
A36: 46118 | B36: Pagamentos funcionários | C36: Saída | D36: Salário | E36: Banco Principal | F36: Pix | G36: 7577.16 | J36: 2026-04 | K36: 7524.05
A37: 46119 | B37: Vendas | C37: Entrada | D37: Vendas | G37: 1634 | J37: 2026-04 | K37: 9158.05
A38: 46119 | B38: Vendas ifood | C38: Entrada | D38: Vendas iFood | E38: Banco Principal | G38: 0 | J38: 2026-04 | K38: 9158.05
A39: 46119 | B39: Motoboy | C39: Saída | D39: iFood | E39: Banco Principal | F39: Pix | G39: 0 | J39: 2026-04 | K39: 9158.05
A40: 46120 | B40: Castanhas promo | C40: Saída | D40: Matéria Prima | E40: Banco Principal | F40: Pix | G40: 689.25 | J40: 2026-04 | K40: 8468.8
...

Sheet MAIO_26
A2: 46143 | B2: Leite | C2: Saída | D2: Matéria Prima | E2: Caixa | F2: Dinheiro | G2: 476 | J2: 2026-05 | K2: 476
A3: 46143 | B3: Vendas | C3: Entrada | D3: Vendas | G3: 9578 | J3: 2026-05 | K3: 10054
A4: 46143 | B4: Vendas Ifood | C4: Entrada | D4: Vendas iFood | E4: Banco Principal | G4: 574 | J4: 2026-05 | K4: 10628
A5: 46143 | B5: Motoboy | C5: Saída | D5: iFood | E5: Banco Principal | F5: Pix | G5: 53 | J5: 2026-05 | K5: 10575
A6: 46144 | B6: Freelancer | C6: Saída | D6: Freelancer | E6: Caixa | F6: Dinheiro | G6: 150 | J6: 2026-05 | K6: 10425
A7: 46144 | B7: VEndas | C7: Entrada | D7: Vendas | G7: 10116 | J7: 2026-05 | K7: 20541
A8: 46144 | B8: Vendas Ifood | C8: Entrada | D8: Vendas iFood | E8: Banco Principal | G8: 55 | J8: 2026-05 | K8: 20596
A9: 46144 | B9: Motoboy | C9: Saída | D9: iFood | E9: Banco Principal | F9: Pix | G9: 9 | J9: 2026-05 | K9: 20587
A10: 46145 | B10: Freelancer | C10: Saída | D10: Freelancer | E10: Caixa | F10: Dinheiro | G10: 150 | J10: 2026-05 | K10: 20437
A11: 46145 | B11: Vendas | C11: Entrada | D11: Vendas | G11: 6795 | J11: 2026-05 | K11: 27232
A12: 46145 | B12: Vendas Ifood | C12: Entrada | D12: Vendas iFood | E12: Banco Principal | G12: 354 | J12: 2026-05 | K12: 27586
A13: 46145 | B13: Motoboy | C13: Saída | D13: iFood | E13: Banco Principal | F13: Pix | G13: 41 | J13: 2026-05 | K13: 27545
A14: 46144 | B14: Diferenca caixa | C14: Saída | D14: Manutenção | E14: Caixa | F14: Dinheiro | G14: 102 | J14: 2026-05 | K14: 27443
A15: 46146 | B15: Creme de leite | C15: Saída | D15: Matéria Prima | E15: Banco Principal | F15: Pix | G15: 709.75 | J15: 2026-05 | K15: 26733.25
A16: 46146 | B16: Riber | C16: Saída | D16: Matéria Prima | E16: Banco Principal | G16: 1029.4 | J16: 2026-05 | K16: 25703.85
A17: 46146 | B17: Riber | C17: Saída | D17: Matéria Prima | E17: Banco Principal | G17: 156.7 | J17: 2026-05 | K17: 25547.15
A18: 46146 | B18: Riber | C18: Saída | D18: Matéria Prima | E18: Banco Principal | G18: 564.36 | J18: 2026-05 | K18: 24982.79
A19: 46146 | B19: Aluguel | C19: Saída | D19: CustoFixo | E19: Banco Principal | G19: 8918.64 | J19: 2026-05 | K19: 16064.15
A20: 46146 | B20: IPTU | C20: Saída | D20: CustoFixo | E20: Banco Principal | F20: Pix | G20: 94.9 | J20: 2026-05 | K20: 15969.25
A21: 46146 | B21: Alarme | C21: Saída | D21: CustoFixo | E21: Banco Principal | G21: 100 | J21: 2026-05 | K21: 15869.25
A22: 46146 | B22: Luz e água mês março | C22: Saída | D22: CustoFixo | E22: Caixa | F22: Dinheiro | G22: 2836.54 | J22: 2026-05 | K22: 13032.71
A23: 46146 | B23: Morango | C23: Saída | D23: Matéria Prima | E23: Banco Principal | G23: 278 | J23: 2026-05 | K23: 12754.71
A24: 46146 | B24: Vendas | C24: Entrada | D24: Vendas | G24: 1145 | J24: 2026-05 | K24: 13899.71
A25: 46146 | B25: Vendas iFood | C25: Entrada | D25: Vendas iFood | E25: Banco Principal | G25: 0 | J25: 2026-05 | K25: 13899.71
A26: 46146 | B26: Motoboy | C26: Saída | D26: iFood | E26: Banco Principal | F26: Pix | G26: 0 | J26: 2026-05 | K26: 13899.71
A27: 46146 | B27: Leite | C27: Saída | D27: Matéria Prima | E27: Caixa | F27: Dinheiro | G27: 0 | J27: 2026-05 | K27: 13899.71
A28: 46147 | B28: Dedetização | C28: Saída | D28: CustoFixo | E28: Banco Principal | F28: Pix | G28: 150 | J28: 2026-05 | K28: 13749.71
A29: 46147 | B29: Impressos | C29: Saída | D29: Mat Consumo | E29: Banco Principal | F29: Pix | G29: 210 | J29: 2026-05 | K29: 13539.71
A30: 46147 | B30: Vendas | C30: Entrada | D30: Vendas | G30: 1471 | J30: 2026-05 | K30: 15010.71
A31: 46147 | B31: Vendas Ifood | C31: Entrada | D31: Vendas iFood | E31: Banco Principal | G31: 84 | J31: 2026-05 | K31: 15094.71
A32: 46147 | B32: Motoboy | C32: Entrada | D32: iFood | E32: Banco Principal | F32: Pix | G32: 27 | J32: 2026-05 | K32: 15121.71
A33: 46147 | B33: Chocolate Blend | C33: Saída | D33: Matéria Prima | E33: Banco Principal | F33: Pix | G33: 3357.6 | J33: 2026-05 | K33: 11764.11
A34: 46148 | B34: Salários | C34: Saída | D34: Salário | E34: Banco Principal | F34: Pix | G34: 9846.01 | J34: 2026-05 | K34: 1918.1
A35: 46148 | B35: 1/3 férias Tais | C35: Saída | D35: Salário | E35: Banco Principal | F35: Pix | G35: 1666.67 | J35: 2026-05 | K35: 251.43
A36: 46148 | B36: Vendas | C36: Entrada | D36: Vendas | G36: 1514 | J36: 2026-05 | K36: 1765.43
A37: 46148 | B37: Vendas iFood | C37: Entrada | D37: Vendas iFood | E37: Banco Principal | G37: 0 | J37: 2026-05 | K37: 1765.43
A38: 46148 | B38: Motoboy | C38: Saída | D38: iFood | E38: Banco Principal | F38: Pix | G38: 0 | J38: 2026-05 | K38: 1765.43
A39: 46148 | B39: Leite | C39: Saída | D39: Matéria Prima | E39: Caixa | F39: Dinheiro | G39: 235 | J39: 2026-05 | K39: 1530.43
A40: 46148 | B40: Salário Tais | C40: Saída | D40: Salário | E40: Banco Principal | F40: Pix | G40: 2000 | J40: 2026-05 | K40: -469.57
A41: 46148 | B41: Cubas | C41: Saída | D41: Salário | E41: Banco Principal | F41: Pix | G41: 279 | J41: 2026-05 | K41: -748.57
...

Sheet JUN_26
A1: Data | B1: Descrição | C1: Tipo | D1: Categoria | E1: Conta | F1: Forma de pagamento | G1: Valor | I1: Obs | J1: Mês | K1: Saldo acumulado
A2: 46174 | B2: Leite | C2: Saída | D2: Matéria Prima | E2: Caixa | F2: Dinheiro | G2: 235 | J2: 2026-06 | K2: =G2 -> 235
A3: 46174 | B3: Tortelli | C3: Saída | D3: Tortelli | E3: Banco Principal | G3: 13185 | J3: 2026-06 | K3: =K2 + IF(C3="Entrada", G3, -G3) -> -12950
A4: 46174 | B4: Unigra | C4: Saída | D4: Matéria Prima | E4: Banco Principal | G4: 4817.04 | J4: 2026-06 | K4: =K3 + IF(C4="Entrada", G4, -G4) -> -17767.04
A5: 46174 | B5: Sistema | C5: Saída | D5: CustoFixo | E5: Banco Principal | G5: 370 | J5: 2026-06 | K5: =K4 + IF(C5="Entrada", G5, -G5) -> -18137.04
A6: 46174 | B6: Tráfego pago | C6: Saída | D6: Marketing | E6: Banco Principal | F6: Pix | G6: 600 | J6: 2026-06 | K6: =K5 + IF(C6="Entrada", G6, -G6) -> -18737.04
A7: 46174 | B7: Vendas | C7: Entrada | D7: Vendas | G7: 454 | J7: 2026-06 | K7: =K6 + IF(C7="Entrada", G7, -G7) -> -18283.04
A8: 46174 | B8: Vendas iFood | C8: Entrada | D8: Vendas iFood | E8: Banco Principal | G8: 32 | J8: 2026-06 | K8: =K7 + IF(C8="Entrada", G8, -G8) -> -18251.04
A9: 46174 | B9: Motoboy | C9: Saída | D9: iFood | E9: Banco Principal | F9: Pix | G9: 13 | J9: 2026-06 | K9: =K8 + IF(C9="Entrada", G9, -G9) -> -18264.04
A10: 46175 | B10: Vendas | C10: Entrada | D10: Vendas | G10: 1001 | J10: 2026-06 | K10: =K9 + IF(C10="Entrada", G10, -G10) -> -17263.04
A11: 46175 | B11: Vendas Ifood | C11: Entrada | D11: Vendas iFood | E11: Banco Principal | G11: 0 | J11: 2026-06 | K11: =K10 + IF(C11="Entrada", G11, -G11) -> -17263.04
A12: 46175 | B12: Motoboy | C12: Saída | D12: iFood | E12: Banco Principal | F12: Pix | G12: 0 | J12: 2026-06 | K12: =K11 + IF(C12="Entrada", G12, -G12) -> -17263.04
A13: 46175 | B13: Boleto Diniz | C13: Saída | D13: Matéria Prima | E13: Banco Principal | G13: 182.54 | J13: 2026-06 | K13: =K12 + IF(C13="Entrada", G13, -G13) -> -17445.58
A14: 46175 | B14: Boleto Riber | C14: Saída | D14: Matéria Prima | E14: Banco Principal | G14: 477.68 | J14: 2026-06 | K14: =K13 + IF(C14="Entrada", G14, -G14) -> -17923.26
A15: 46175 | B15: Limão | C15: Saída | D15: Matéria Prima | E15: Banco Principal | F15: Pix | G15: 130 | J15: 2026-06 | K15: =K14 + IF(C15="Entrada", G15, -G15) -> -18053.26
A16: 46175 | B16: Paflo, lampada e cola | C16: Saída | D16: Manutenção | E16: Banco Principal | F16: Pix | G16: 50.7 | J16: 2026-06 | K16: =K15 + IF(C16="Entrada", G16, -G16) -> -18103.96
A17: 46175 | B17: Luany domingo adiantado | C17: Saída | D17: Freelancer | E17: Banco Principal | F17: Pix | G17: 150 | J17: 2026-06 | K17: =K16 + IF(C17="Entrada", G17, -G17) -> -18253.96
A18: 46176 | B18: Salário Tais | C18: Saída | D18: Salário | E18: Banco Principal | F18: Pix | G18: 5000 | J18: 2026-06 | K18: =K17 + IF(C18="Entrada", G18, -G18) -> -23253.96
A19: 46176 | B19: Boleto Ecila | C19: Saída | D19: Matéria Prima | E19: Banco Principal | G19: 115.8 | J19: 2026-06 | K19: =K18 + IF(C19="Entrada", G19, -G19) -> -23369.76
A20: 46176 | B20: Vendas | C20: Entrada | D20: Vendas | G20: 1413 | J20: 2026-06 | K20: =K19 + IF(C20="Entrada", G20, -G20) -> -21956.76
A21: 46176 | B21: Vendas iFood | C21: Entrada | D21: Vendas iFood | E21: Banco Principal | G21: 0 | J21: 2026-06 | K21: =K20 + IF(C21="Entrada", G21, -G21) -> -21956.76
A22: 46176 | B22: Motoboy | C22: Saída | D22: iFood | E22: Banco Principal | F22: Pix | G22: 0 | J22: 2026-06 | K22: =K21 + IF(C22="Entrada", G22, -G22) -> -21956.76
A23: 46177 | B23: Vendas | C23: Entrada | D23: Vendas | G23: 5165 | J23: 2026-06 | K23: =K22 + IF(C23="Entrada", G23, -G23) -> -16791.76
A24: 46177 | B24: Vendas Ifood | C24: Entrada | D24: Vendas iFood | E24: Banco Principal | G24: 0 | J24: 2026-06 | K24: =K23 + IF(C24="Entrada", G24, -G24) -> -16791.76
A25: 46177 | B25: Motoboy | C25: Saída | D25: iFood | E25: Banco Principal | F25: Pix | G25: 0 | J25: 2026-06 | K25: =K24 + IF(C25="Entrada", G25, -G25) -> -16791.76
A26: 46177 | B26: Leite | C26: Saída | D26: Matéria Prima | E26: Caixa | F26: Dinheiro | G26: 235 | J26: 2026-06 | K26: =K25 + IF(C26="Entrada", G26, -G26) -> -17026.76
A27: 46178 | B27: Vendas | C27: Entrada | D27: Vendas | G27: 6234 | J27: 2026-06 | K27: =K26 + IF(C27="Entrada", G27, -G27) -> -10792.76
A28: 46178 | B28: Vendas Ifood | C28: Entrada | D28: Vendas iFood | E28: Banco Principal | G28: 168 | J28: 2026-06 | K28: =K27 + IF(C28="Entrada", G28, -G28) -> -10624.76
A29: 46178 | B29: Motoboy | C29: Saída | D29: iFood | E29: Banco Principal | F29: Pix | G29: 35 | J29: 2026-06 | K29: =K28 + IF(C29="Entrada", G29, -G29) -> -10659.76
A30: 46178 | B30: Salarios | C30: Saída | D30: Salário | E30: Banco Principal | F30: Pix | G30: 6890.33 | J30: 2026-06 | K30: =K29 + IF(C30="Entrada", G30, -G30) -> -17550.09
A31: 46178 | B31: Aluguel | C31: Saída | D31: CustoFixo | E31: Banco Principal | G31: 8918.64 | J31: 2026-06 | K31: =K30 + IF(C31="Entrada", G31, -G31) -> -26468.73
A32: 46178 | B32: IPTU | C32: Saída | D32: CustoFixo | E32: Banco Principal | F32: Pix | G32: 94.9 | J32: 2026-06 | K32: =K31 + IF(C32="Entrada", G32, -G32) -> -26563.63
A33: 46178 | B33: Alarme | C33: Saída | D33: CustoFixo | E33: Banco Principal | G33: 100 | J33: 2026-06 | K33: =K32 + IF(C33="Entrada", G33, -G33) -> -26663.63
